<mujoco model="panther">
  <compiler angle="radian" meshdir="assets"/>
  <asset>
    <mesh name="body" file="body.stl"/>
    <mesh name="body_collision" file="body_collision.stl"/>
    <mesh name="fl_wheel" file="fl_wheel.stl"/>
    <mesh name="wheel_collision" file="wheel_collision.stl"/>
    <mesh name="fr_wheel" file="fr_wheel.stl"/>
    <mesh name="rl_wheel" file="rl_wheel.stl"/>
    <mesh name="rr_wheel" file="rr_wheel.stl"/>
  </asset>
  <worldbody>
    <body name="panther" pos= '0 0 1'>
      <geom rgba='1 0 0 1' pos="0 0 0.1825" type="mesh" contype="0" conaffinity="0" group="1" density="0" mesh="body"/>
      <geom rgba='0 0 0 0' pos="0 0 0.1825" type="mesh" mesh="body_collision"/>
      <body name="fl_wheel_link" pos="0.22 0.3485 0.1825">
        <inertial pos="0 0 0" quat="0.707107 0 0 0.707107" mass="3" diaginertia="0.03485 0.02251 0.02251"/>
        <joint name="fl_wheel_joint" pos="0 0 0" axis="0 1 0" actuatorfrcrange="-34.5 34.5" damping="0.01" frictionloss="0.01"/>
        <geom rgba='0 0 0 1' type="mesh" contype="0" conaffinity="0" group="1" density="0" mesh="fl_wheel"/>
        <geom rgba='0 0 0 0' type="mesh" mesh="wheel_collision"/>
      </body>
      <body name="fr_wheel_link" pos="0.22 -0.3485 0.1825">
        <inertial pos="0 0 0" quat="0.707107 0 0 0.707107" mass="3" diaginertia="0.03485 0.02251 0.02251"/>
        <joint name="fr_wheel_joint" pos="0 0 0" axis="0 1 0" actuatorfrcrange="-34.5 34.5" damping="0.01" frictionloss="0.01"/>
        <geom rgba='0 0 0 1' type="mesh" contype="0" conaffinity="0" group="1" density="0" mesh="fr_wheel"/>
        <geom rgba='0 0 0 0' type="mesh" mesh="wheel_collision"/>
      </body>
      <body name="rl_wheel_link" pos="-0.22 0.3485 0.1825">
        <inertial pos="0 0 0" quat="0.707107 0 0 0.707107" mass="3" diaginertia="0.03485 0.02251 0.02251"/>
        <joint name="rl_wheel_joint" pos="0 0 0" axis="0 1 0" actuatorfrcrange="-34.5 34.5" damping="0.01" frictionloss="0.01"/>
        <geom rgba='0 0 0 1' type="mesh" contype="0" conaffinity="0" group="1" density="0" mesh="rl_wheel"/>
        <geom rgba='0 0 0 0' type="mesh" mesh="wheel_collision"/>
      </body>
      <body name="rr_wheel_link" pos="-0.22 -0.3485 0.1825">
        <inertial pos="0 0 0" quat="0.707107 0 0 0.707107" mass="3" diaginertia="0.03485 0.02251 0.02251"/>
        <joint name="rr_wheel_joint" pos="0 0 0" axis="0 1 0" actuatorfrcrange="-34.5 34.5" damping="0.01" frictionloss="0.01"/>
        <geom rgba='0 0 0 1' type="mesh" contype="0" conaffinity="0" group="1" density="0" mesh="rr_wheel"/>
        <geom rgba='0 0 0 0' type="mesh" mesh="wheel_collision"/>
      </body>
    </body>
  </worldbody>

  <tendon>
      <fixed name="linear">
        <joint joint="fl_wheel_joint"  coef="1"/>
        <joint joint="fr_wheel_joint" coef="1"/>
        <joint joint="rl_wheel_joint"   coef="1"/>
        <joint joint="rr_wheel_joint"  coef="1"/>
      </fixed>
      <fixed name="angular">
        <joint joint="fl_wheel_joint"  coef="-1"/>
        <joint joint="fr_wheel_joint" coef="1"/>
        <joint joint="rl_wheel_joint"   coef="-1"/>
        <joint joint="rr_wheel_joint"  coef="1"/>
      </fixed>
    </tendon>
  
    <actuator>
      <motor name="linear"  tendon="linear"  ctrlrange="-2.5 2.5"/>
      <motor name="angular" tendon="angular" ctrlrange="-10 10"/>
    </actuator>
  
    <sensor>
      <jointactuatorfrc name="fr_wheel_joint_trq" joint="fr_wheel_joint"/>
      <jointactuatorfrc name="fl_wheel_joint_trq"  joint="fl_wheel_joint"/>
      <jointactuatorfrc name="rr_wheel_joint_trq"  joint="rr_wheel_joint"/>
      <jointactuatorfrc name="rl_wheel_joint_trq"   joint="rl_wheel_joint"/>
      <jointpos         name="fl_wheel_joint_pos"  joint="fl_wheel_joint"  noise="0.01" />
      <jointpos         name="fr_wheel_joint_pos" joint="fr_wheel_joint" noise="0.01" />
      <jointpos         name="rl_wheel_joint_pos"   joint="rl_wheel_joint"   noise="0.01" />
      <jointpos         name="rr_wheel_joint_pos"  joint="rr_wheel_joint"  noise="0.01" />
      <jointvel         name="fr_wheel_joint_vel" joint="fr_wheel_joint" noise="0.01"/>
      <jointvel         name="fl_wheel_joint_vel"  joint="fl_wheel_joint"  noise="0.01"/>
      <jointvel         name="rr_wheel_joint_vel"  joint="rr_wheel_joint"  noise="0.01"/>
      <jointvel         name="rl_wheel_joint_vel"   joint="rl_wheel_joint"   noise="0.01"/>
    </sensor>
</mujoco>
